  File "/nix/store/clx0mcir7qw8zk36zbr4jra789g3knf6-python3-3.11.10/lib/python3.11/concurrent/futures/_base.py", line 401, in __get_result
    raise self._exception
  File "/home/runner/workspace/.pythonlibs/lib/python3.11/site-packages/tenacity/__init__.py", line 478, in __call__
    result = fn(*args, **kwargs)
             ^^^^^^^^^^^^^^^^^^^
  File "/home/runner/workspace/.pythonlibs/lib/python3.11/site-packages/chromadb/api/segment.py", line 103, in wrapper
    return self._rate_limit_enforcer.rate_limit(func)(*args, **kwargs)
           ^^^^^^^^^^^^^^^^^^^^^^^^^^^^^^^^^^^^^^^^^^^^^^^^^^^^^^^^^^^
  File "/home/runner/workspace/.pythonlibs/lib/python3.11/site-packages/chromadb/rate_limit/simple_rate_limit/__init__.py", line 24, in wrapper
    return func(*args, **kwargs)
           ^^^^^^^^^^^^^^^^^^^^^
  File "/home/runner/workspace/.pythonlibs/lib/python3.11/site-packages/chromadb/api/segment.py", line 805, in _query
    self._validate_dimension(scan.collection, len(embedding), update=False)
  File "/home/runner/workspace/.pythonlibs/lib/python3.11/site-packages/chromadb/api/segment.py", line 896, in _validate_dimension
    raise InvalidDimensionException(
chromadb.errors.InvalidDimensionException: Embedding dimension 1536 does not match collection dimensionality 3072
INFO:     [17-03-2025 23:48:51] 127.0.0.1:47222 - "GET /api/v2/tenants/default_tenant HTTP/1.1" 200
INFO:     [17-03-2025 23:48:51] 127.0.0.1:47232 - "GET /api/v2/tenants/default_tenant/databases/default_database HTTP/1.1" 200
INFO:     [17-03-2025 23:48:51] 127.0.0.1:47222 - "GET /api/v2/tenants/default_tenant/databases/default_database/collections HTTP/1.1" 200
INFO:     [17-03-2025 23:48:51] 127.0.0.1:47232 - "GET /api/v2/tenants/default_tenant/databases/default_database/collections/knowledge_base HTTP/1.1" 200
INFO:     [17-03-2025 23:48:52] 127.0.0.1:47222 - "POST /api/v2/tenants/default_tenant/databases/default_database/collections/60f0e47c-9f31-43a7-a691-d6ed820117b7/query HTTP/1.1" 400
ERROR:    [17-03-2025 23:48:52] Exception in ASGI application
Traceback (most recent call last):
  File "/home/runner/workspace/.pythonlibs/lib/python3.11/site-packages/anyio/streams/memory.py", line 111, in receive
    return self.receive_nowait()
           ^^^^^^^^^^^^^^^^^^^^^
  File "/home/runner/workspace/.pythonlibs/lib/python3.11/site-packages/anyio/streams/memory.py", line 106, in receive_nowait
    raise WouldBlock
anyio.WouldBlock

During handling of the above exception, another exception occurred:

Traceback (most recent call last):
  File "/home/runner/workspace/.pythonlibs/lib/python3.11/site-packages/anyio/streams/memory.py", line 124, in receive
    return receiver.item
           ^^^^^^^^^^^^^
AttributeError: 'MemoryObjectItemReceiver' object has no attribute 'item'

During handling of the above exception, another exception occurred:

Traceback (most recent call last):
  File "/home/runner/workspace/.pythonlibs/lib/python3.11/site-packages/starlette/middleware/base.py", line 147, in call_next
    message = await recv_stream.receive()
              ^^^^^^^^^^^^^^^^^^^^^^^^^^^
  File "/home/runner/workspace/.pythonlibs/lib/python3.11/site-packages/anyio/streams/memory.py", line 126, in receive
    raise EndOfStream
anyio.EndOfStream

During handling of the above exception, another exception occurred:

Traceback (most recent call last):
  File "/home/runner/workspace/.pythonlibs/lib/python3.11/site-packages/uvicorn/protocols/http/httptools_impl.py", line 409, in run_asgi
    result = await app(  # type: ignore[func-returns-value]
             ^^^^^^^^^^^^^^^^^^^^^^^^^^^^^^^^^^^^^^^^^^^^^^
  File "/home/runner/workspace/.pythonlibs/lib/python3.11/site-packages/uvicorn/middleware/proxy_headers.py", line 60, in __call__
    return await self.app(scope, receive, send)
           ^^^^^^^^^^^^^^^^^^^^^^^^^^^^^^^^^^^^
  File "/home/runner/workspace/.pythonlibs/lib/python3.11/site-packages/fastapi/applications.py", line 1054, in __call__
    await super().__call__(scope, receive, send)
  File "/home/runner/workspace/.pythonlibs/lib/python3.11/site-packages/starlette/applications.py", line 112, in __call__
    await self.middleware_stack(scope, receive, send)
  File "/home/runner/workspace/.pythonlibs/lib/python3.11/site-packages/starlette/middleware/errors.py", line 187, in __call__
    raise exc
  File "/home/runner/workspace/.pythonlibs/lib/python3.11/site-packages/starlette/middleware/errors.py", line 165, in __call__
    await self.app(scope, receive, _send)
  File "/home/runner/workspace/.pythonlibs/lib/python3.11/site-packages/opentelemetry/instrumentation/asgi/__init__.py", line 743, in __call__
    await self.app(scope, otel_receive, otel_send)
  File "/home/runner/workspace/.pythonlibs/lib/python3.11/site-packages/starlette/middleware/cors.py", line 85, in __call__
    await self.app(scope, receive, send)
  File "/home/runner/workspace/.pythonlibs/lib/python3.11/site-packages/starlette/middleware/base.py", line 181, in __call__
    raise app_exc
  File "/home/runner/workspace/.pythonlibs/lib/python3.11/site-packages/starlette/middleware/base.py", line 140, in coro
    await self.app(scope, receive_or_disconnect, send_no_error)
  File "/home/runner/workspace/.pythonlibs/lib/python3.11/site-packages/starlette/middleware/base.py", line 181, in __call__
    raise app_exc
  File "/home/runner/workspace/.pythonlibs/lib/python3.11/site-packages/chromadb/server/fastapi/__init__.py", line 120, in catch_exceptions_middleware
    return await call_next(request)
           ^^^^^^^^^^^^^^^^^^^^^^^^
  File "/home/runner/workspace/.pythonlibs/lib/python3.11/site-packages/starlette/middleware/base.py", line 153, in call_next
    raise app_exc
  File "/home/runner/workspace/.pythonlibs/lib/python3.11/site-packages/starlette/middleware/base.py", line 140, in coro
    await self.app(scope, receive_or_disconnect, send_no_error)
  File "/home/runner/workspace/.pythonlibs/lib/python3.11/site-packages/starlette/middleware/base.py", line 173, in __call__
    with recv_stream, send_stream, collapse_excgroups():
  File "/nix/store/clx0mcir7qw8zk36zbr4jra789g3knf6-python3-3.11.10/lib/python3.11/contextlib.py", line 158, in __exit__
    self.gen.throw(typ, value, traceback)
  File "/home/runner/workspace/.pythonlibs/lib/python3.11/site-packages/starlette/_utils.py", line 82, in collapse_excgroups
    raise exc
  File "/home/runner/workspace/.pythonlibs/lib/python3.11/site-packages/starlette/middleware/base.py", line 175, in __call__
    response = await self.dispatch_func(request, call_next)
               ^^^^^^^^^^^^^^^^^^^^^^^^^^^^^^^^^^^^^^^^^^^^
  File "/home/runner/workspace/.pythonlibs/lib/python3.11/site-packages/chromadb/server/fastapi/__init__.py", line 144, in check_http_version_middleware
    return await call_next(request)
           ^^^^^^^^^^^^^^^^^^^^^^^^
  File "/home/runner/workspace/.pythonlibs/lib/python3.11/site-packages/starlette/middleware/base.py", line 153, in call_next
    raise app_exc
  File "/home/runner/workspace/.pythonlibs/lib/python3.11/site-packages/starlette/middleware/base.py", line 140, in coro
    await self.app(scope, receive_or_disconnect, send_no_error)
  File "/home/runner/workspace/.pythonlibs/lib/python3.11/site-packages/starlette/middleware/exceptions.py", line 62, in __call__
    await wrap_app_handling_exceptions(self.app, conn)(scope, receive, send)
  File "/home/runner/workspace/.pythonlibs/lib/python3.11/site-packages/starlette/_exception_handler.py", line 53, in wrapped_app
    raise exc
  File "/home/runner/workspace/.pythonlibs/lib/python3.11/site-packages/starlette/_exception_handler.py", line 42, in wrapped_app
    await app(scope, receive, sender)
  File "/home/runner/workspace/.pythonlibs/lib/python3.11/site-packages/starlette/routing.py", line 714, in __call__
    await self.middleware_stack(scope, receive, send)
  File "/home/runner/workspace/.pythonlibs/lib/python3.11/site-packages/starlette/routing.py", line 734, in app
    await route.handle(scope, receive, send)
  File "/home/runner/workspace/.pythonlibs/lib/python3.11/site-packages/starlette/routing.py", line 288, in handle
    await self.app(scope, receive, send)
  File "/home/runner/workspace/.pythonlibs/lib/python3.11/site-packages/starlette/routing.py", line 76, in app
    await wrap_app_handling_exceptions(app, request)(scope, receive, send)
  File "/home/runner/workspace/.pythonlibs/lib/python3.11/site-packages/starlette/_exception_handler.py", line 53, in wrapped_app
    raise exc
  File "/home/runner/workspace/.pythonlibs/lib/python3.11/site-packages/starlette/_exception_handler.py", line 42, in wrapped_app
    await app(scope, receive, sender)
  File "/home/runner/workspace/.pythonlibs/lib/python3.11/site-packages/starlette/routing.py", line 73, in app
    response = await f(request)
               ^^^^^^^^^^^^^^^^
  File "/home/runner/workspace/.pythonlibs/lib/python3.11/site-packages/fastapi/routing.py", line 301, in app
    raw_response = await run_endpoint_function(
                   ^^^^^^^^^^^^^^^^^^^^^^^^^^^^
  File "/home/runner/workspace/.pythonlibs/lib/python3.11/site-packages/fastapi/routing.py", line 212, in run_endpoint_function
    return await dependant.call(**values)
           ^^^^^^^^^^^^^^^^^^^^^^^^^^^^^^
  File "/home/runner/workspace/.pythonlibs/lib/python3.11/site-packages/chromadb/telemetry/opentelemetry/__init__.py", line 134, in async_wrapper
    return await f(*args, **kwargs)
           ^^^^^^^^^^^^^^^^^^^^^^^^
  File "/home/runner/workspace/.pythonlibs/lib/python3.11/site-packages/chromadb/server/fastapi/__init__.py", line 92, in wrapper
    return await self._async_rate_limit_enforcer.rate_limit(func)(*args, **kwargs)
           ^^^^^^^^^^^^^^^^^^^^^^^^^^^^^^^^^^^^^^^^^^^^^^^^^^^^^^^^^^^^^^^^^^^^^^^
  File "/home/runner/workspace/.pythonlibs/lib/python3.11/site-packages/chromadb/rate_limit/simple_rate_limit/__init__.py", line 41, in wrapper
    return await func(*args, **kwargs)
           ^^^^^^^^^^^^^^^^^^^^^^^^^^^
  File "/home/runner/workspace/.pythonlibs/lib/python3.11/site-packages/chromadb/server/fastapi/__init__.py", line 1216, in get_nearest_neighbors
    await to_thread.run_sync(
  File "/home/runner/workspace/.pythonlibs/lib/python3.11/site-packages/anyio/to_thread.py", line 56, in run_sync
    return await get_async_backend().run_sync_in_worker_thread(
           ^^^^^^^^^^^^^^^^^^^^^^^^^^^^^^^^^^^^^^^^^^^^^^^^^^^^
  File "/home/runner/workspace/.pythonlibs/lib/python3.11/site-packages/anyio/_backends/_asyncio.py", line 2461, in run_sync_in_worker_thread
    return await future
           ^^^^^^^^^^^^
  File "/home/runner/workspace/.pythonlibs/lib/python3.11/site-packages/anyio/_backends/_asyncio.py", line 962, in run
    result = context.run(func, *args)
             ^^^^^^^^^^^^^^^^^^^^^^^^
  File "/home/runner/workspace/.pythonlibs/lib/python3.11/site-packages/chromadb/server/fastapi/__init__.py", line 1198, in process_query
    return self._api._query(
           ^^^^^^^^^^^^^^^^^
  File "/home/runner/workspace/.pythonlibs/lib/python3.11/site-packages/chromadb/telemetry/opentelemetry/__init__.py", line 150, in wrapper
    return f(*args, **kwargs)
           ^^^^^^^^^^^^^^^^^^
  File "/home/runner/workspace/.pythonlibs/lib/python3.11/site-packages/tenacity/__init__.py", line 336, in wrapped_f
    return copy(f, *args, **kw)
           ^^^^^^^^^^^^^^^^^^^^
  File "/home/runner/workspace/.pythonlibs/lib/python3.11/site-packages/tenacity/__init__.py", line 475, in __call__
    do = self.iter(retry_state=retry_state)
         ^^^^^^^^^^^^^^^^^^^^^^^^^^^^^^^^^^
  File "/home/runner/workspace/.pythonlibs/lib/python3.11/site-packages/tenacity/__init__.py", line 376, in iter
    result = action(retry_state)
             ^^^^^^^^^^^^^^^^^^^
  File "/home/runner/workspace/.pythonlibs/lib/python3.11/site-packages/tenacity/__init__.py", line 398, in <lambda>
    self._add_action_func(lambda rs: rs.outcome.result())
                                     ^^^^^^^^^^^^^^^^^^^
  File "/nix/store/clx0mcir7qw8zk36zbr4jra789g3knf6-python3-3.11.10/lib/python3.11/concurrent/futures/_base.py", line 449, in result
    return self.__get_result()
           ^^^^^^^^^^^^^^^^^^^
  File "/nix/store/clx0mcir7qw8zk36zbr4jra789g3knf6-python3-3.11.10/lib/python3.11/concurrent/futures/_base.py", line 401, in __get_result
    raise self._exception
  File "/home/runner/workspace/.pythonlibs/lib/python3.11/site-packages/tenacity/__init__.py", line 478, in __call__
    result = fn(*args, **kwargs)
             ^^^^^^^^^^^^^^^^^^^
  File "/home/runner/workspace/.pythonlibs/lib/python3.11/site-packages/chromadb/api/segment.py", line 103, in wrapper
    return self._rate_limit_enforcer.rate_limit(func)(*args, **kwargs)
           ^^^^^^^^^^^^^^^^^^^^^^^^^^^^^^^^^^^^^^^^^^^^^^^^^^^^^^^^^^^
  File "/home/runner/workspace/.pythonlibs/lib/python3.11/site-packages/chromadb/rate_limit/simple_rate_limit/__init__.py", line 24, in wrapper
    return func(*args, **kwargs)
           ^^^^^^^^^^^^^^^^^^^^^
  File "/home/runner/workspace/.pythonlibs/lib/python3.11/site-packages/chromadb/api/segment.py", line 805, in _query
    self._validate_dimension(scan.collection, len(embedding), update=False)
  File "/home/runner/workspace/.pythonlibs/lib/python3.11/site-packages/chromadb/api/segment.py", line 896, in _validate_dimension
    raise InvalidDimensionException(
chromadb.errors.InvalidDimensionException: Embedding dimension 1536 does not match collection dimensionality 3072
